<?xml version="1.0"?>
<robot xmlns:xacro="http://www.ros.org/wiki/xacro" name="joint_macros">

  <xacro:macro name="rotor_joint" params="">
    <joint name="rotor_joint" type="revolute">

      <parent link="base_link"/>
      <child link="rotor_link"/>

      <origin xyz="0 0 ${base_height+rotor_height+pendulum_height}" rpy="0 0 0"/>

      <axis xyz="0 0 1"/>

      <limit effort="100" velocity="200" lower="-2.35619" upper="2.35619"/>

      <dynamics damping="${rotor_damping}" friction="${rotor_friction}"/>

    </joint>
  </xacro:macro>

</robot>
